Workbook
Name Slicer_Clinic_Location: #N/A

Sheet Veterinary Clinic Dashboard
A9: Clinic Location | B9: Revenue | I9: Treatment | J9: Revenue
A10: Baltimore | B10: 46333.786 | I10: Annual Bloodwork | J10: 22102.735
A11: Frederick | B11: 83111.621 | I11: Dental Cleaning | J11: 18746.95
A12: Rockville | B12: 40212.812 | I12: Emergency Visit | J12: 19799.898
A13: Grand Total | B13: 169658.22 | I13: Nail Trim | J13: 21260.612
I14: Office Visit | J14: 16734.634
I15: Radiographs | J15: 27250.813
I16: Surgery | J16: 27917.403
I17: Vaccination | J17: 15845.174
I18: Grand Total | J18: 169658.22
A25: Number of Visits | B25: Location
A26: Treatments | B26: Baltimore | C26: Frederick | D26: Rockville | E26: Grand Total
A27: Annual Bloodwork | B27: 15 | C27: 28 | D27: 20 | E27: 63
A28: Dental Cleaning | B28: 14 | C28: 27 | D28: 14 | E28: 55
A29: Emergency Visit | B29: 15 | C29: 30 | D29: 15 | E29: 60
A30: Nail Trim | B30: 21 | C30: 35 | D30: 9 | E30: 65
A31: Office Visit | B31: 20 | C31: 28 | D31: 11 | E31: 59
A32: Radiographs | B32: 23 | C32: 26 | D32: 19 | E32: 68
A33: Surgery | B33: 20 | C33: 38 | D33: 16 | E33: 74
A34: Vaccination | B34: 13 | C34: 29 | D34: 14 | E34: 56
A35: Grand Total | B35: 141 | C35: 241 | D35: 118 | E35: 500

Sheet Data Cleaning Notes
A1: Data_Cleaning_Steps
A3: Fixed inconsistent capitalization (DOG → Dog)
A4: Corrected misspelled treatments
A5: Standardized clinic locations
A6: Removed duplicates (if any)
A7: Validated charge codes against reference table

Sheet Visits_Clean
A1: Visit_ID | B1: Pet_ID | C1: Owner_ID | D1: Pet_Name | E1: Species | F1: Breed | G1: Visit_Date | H1: Treatment | I1: Charge_Code | J1: Charge_Amount | K1: Clinic_Location
A2: 1 | B2: 47 | C2: 116 | D2: Winston | E2: Dog | F2: Shih Tzu | G2: 03/28/2023 | H2: =_xlfn.XLOOKUP(Vet_Visits[[#This Row],[Charge_Code]],Charge_Reference!A:A,Charge_Reference!B:B) -> Surgery | I2: SUR04 | J2: 939.0052 | K2: Rockville
A3: 2 | B3: 25 | C3: 37 | D3: Ellie | E3: Dog | F3: German Shepherd | G3: 01/09/2023 | H3: =_xlfn.XLOOKUP(Vet_Visits[[#This Row],[Charge_Code]],Charge_Reference!A:A,Charge_Reference!B:B) -> Emergency Visit | I3: EM06 | J3: 725.9805 | K3: Rockville
A4: 3 | B4: 22 | C4: 35 | D4: Rocky | E4: Dog | F4: Beagle | G4: 11/14/2023 | H4: =_xlfn.XLOOKUP(Vet_Visits[[#This Row],[Charge_Code]],Charge_Reference!A:A,Charge_Reference!B:B) -> Annual Bloodwork | I4: BW07 | J4: 349.3595 | K4: Frederick
A5: 4 | B5: 63 | C5: 66 | D5: Ellie | E5: Cat | F5: Yorkshire Terrier | G5: 01/02/2023 | H5: =_xlfn.XLOOKUP(Vet_Visits[[#This Row],[Charge_Code]],Charge_Reference!A:A,Charge_Reference!B:B) -> Emergency Visit | I5: EM06 | J5: 78.2418 | K5: Frederick
A6: 5 | B6: 18 | C6: 101 | D6: Riley | E6: Dog | F6: Border Collie | G6: 11/05/2023 | H6: =_xlfn.XLOOKUP(Vet_Visits[[#This Row],[Charge_Code]],Charge_Reference!A:A,Charge_Reference!B:B) -> Dental Cleaning | I6: DEN02 | J6: 480.2783 | K6: Frederick
A7: 6 | B7: 71 | C7: 131 | D7: Shadow | E7: Cat | F7: Chihuahua | G7: 10/19/2023 | H7: =_xlfn.XLOOKUP(Vet_Visits[[#This Row],[Charge_Code]],Charge_Reference!A:A,Charge_Reference!B:B) -> Radiographs | I7: RAD08 | J7: 937.5625 | K7: Rockville
A8: 7 | B8: 92 | C8: 75 | D8: Rosie | E8: Dog | F8: Poodle | G8: 01/29/2023 | H8: =_xlfn.XLOOKUP(Vet_Visits[[#This Row],[Charge_Code]],Charge_Reference!A:A,Charge_Reference!B:B) -> Vaccination | I8: VAC01 | J8: 650.0059 | K8: Frederick
A9: 8 | B9: 12 | C9: 2 | D9: Nova | E9: Dog | F9: Labrador Retriever | G9: 04/07/2023 | H9: =_xlfn.XLOOKUP(Vet_Visits[[#This Row],[Charge_Code]],Charge_Reference!A:A,Charge_Reference!B:B) -> Office Visit | I9: CHK03 | J9: -244.7196 | K9: Frederick
A10: 9 | B10: 192 | C10: 107 | D10: Loki | E10: Dog | F10: Ragdoll | G10: 11/20/2023 | H10: =_xlfn.XLOOKUP(Vet_Visits[[#This Row],[Charge_Code]],Charge_Reference!A:A,Charge_Reference!B:B) -> Dental Cleaning | I10: DEN02 | J10: 249.9214 | K10: Rockville
A11: 10 | B11: 92 | C11: 20 | D11: Winston | E11: Dog | F11: Border Collie | G11: 05/28/2023 | H11: =_xlfn.XLOOKUP(Vet_Visits[[#This Row],[Charge_Code]],Charge_Reference!A:A,Charge_Reference!B:B) -> Nail Trim | I11: NT05 | J11: 866.7261 | K11: Frederick
A12: 11 | B12: 124 | C12: 72 | D12: Max | E12: Dog | F12: Scottish Fold | G12: 06/01/2023 | H12: =_xlfn.XLOOKUP(Vet_Visits[[#This Row],[Charge_Code]],Charge_Reference!A:A,Charge_Reference!B:B) -> Office Visit | I12: CHK03 | J12: 738.0413 | K12: Frederick
A13: 12 | B13: 17 | C13: 117 | D13: Oliver | E13: Dog | F13: Shih Tzu | G13: 08/08/2023 | H13: =_xlfn.XLOOKUP(Vet_Visits[[#This Row],[Charge_Code]],Charge_Reference!A:A,Charge_Reference!B:B) -> Office Visit | I13: CHK03 | J13: 66.0608 | K13: Baltimore
... A501: 500 | B501: 168 | C501: 72 | D501: Bentley | E501: Cat | F501: Border Collie | G501: 05/24/2023 | H501: =_xlfn.XLOOKUP(Vet_Visits[[#This Row],[Charge_Code]],Charge_Reference!A:A,Charge_Reference!B:B) -> Nail Trim | I501: NT05 | J501: 513.7263 | K501: Frederick

Sheet Sheet2
A1: Treatment | B1: (All)
A3: Row Labels | B3: Sum of Charge_Amount
A4: Cat | B4: 79279.19
A5: Dog | B5: 90379.029
A6: Grand Total | B6: 169658.22

Sheet Visits Cleaned
A1: Visit_ID | B1: Pet_ID | C1: Owner_ID | D1: Pet_Name | E1: Species | F1: Breed | G1: Visit_Date | H1: Charge_Code | I1: Treatment | J1: Charge_Amount | K1: Clinic_Location | L1: Surgery_PostOp
A2: 1 | B2: 47 | C2: 116 | D2: Winston | E2: Dog | F2: Shih Tzu | G2: 03/28/2023 | H2: SUR04 | I2: =_xlfn.XLOOKUP(H2,Charge_Reference!A:A,Charge_Reference!B:B) -> Surgery | J2: 939.0052 | K2: Rockville | L2: =IF(I2 = "Surgery", "Needs TGH instructions", "No instructions needed") -> Needs TGH instructions
A3: 2 | B3: 25 | C3: 37 | D3: Ellie | E3: Dog | F3: German Shepherd | G3: 01/09/2023 | H3: EM06 | I3: =_xlfn.XLOOKUP(H3,Charge_Reference!A:A,Charge_Reference!B:B) -> Emergency Visit | J3: 725.9805 | K3: Rockville | L3: =IF(I3 = "Surgery", "Needs TGH instructions", "No instructions needed") -> No instructions needed | S3: Column1
A4: 3 | B4: 22 | C4: 35 | D4: Rocky | E4: Dog | F4: Beagle | G4: 11/14/2023 | H4: BW07 | I4: =_xlfn.XLOOKUP(H4,Charge_Reference!A:A,Charge_Reference!B:B) -> Annual Bloodwork | J4: 349.3595 | K4: Frederick | L4: =IF(I4 = "Surgery", "Needs TGH instructions", "No instructions needed") -> No instructions needed
A5: 4 | B5: 63 | C5: 66 | D5: Ellie | E5: Cat | F5: Yorkshire Terrier | G5: 01/02/2023 | H5: EM06 | I5: =_xlfn.XLOOKUP(H5,Charge_Reference!A:A,Charge_Reference!B:B) -> Emergency Visit | J5: 78.2418 | K5: Frederick | L5: =IF(I5 = "Surgery", "Needs TGH instructions", "No instructions needed") -> No instructions needed | S5: Mean | T5: 339.31644
A6: 5 | B6: 18 | C6: 101 | D6: Riley | E6: Dog | F6: Border Collie | G6: 11/05/2023 | H6: DEN02 | I6: =_xlfn.XLOOKUP(H6,Charge_Reference!A:A,Charge_Reference!B:B) -> Dental Cleaning | J6: 480.2783 | K6: Frederick | L6: =IF(I6 = "Surgery", "Needs TGH instructions", "No instructions needed") -> No instructions needed | S6: Standard Error | T6: 16.899492
A7: 6 | B7: 71 | C7: 131 | D7: Shadow | E7: Cat | F7: Chihuahua | G7: 10/19/2023 | H7: RAD08 | I7: =_xlfn.XLOOKUP(H7,Charge_Reference!A:A,Charge_Reference!B:B) -> Radiographs | J7: 937.5625 | K7: Rockville | L7: =IF(I7 = "Surgery", "Needs TGH instructions", "No instructions needed") -> No instructions needed | S7: Median | T7: 319.58565
A8: 7 | B8: 92 | C8: 75 | D8: Rosie | E8: Dog | F8: Poodle | G8: 01/29/2023 | H8: VAC01 | I8: =_xlfn.XLOOKUP(H8,Charge_Reference!A:A,Charge_Reference!B:B) -> Vaccination | J8: 650.0059 | K8: Frederick | L8: =IF(I8 = "Surgery", "Needs TGH instructions", "No instructions needed") -> No instructions needed | S8: Mode | T8: #N/A
A9: 8 | B9: 12 | C9: 2 | D9: Nova | E9: Dog | F9: Labrador Retriever | G9: 04/07/2023 | H9: CHK03 | I9: =_xlfn.XLOOKUP(H9,Charge_Reference!A:A,Charge_Reference!B:B) -> Office Visit | J9: -244.7196 | K9: Frederick | L9: =IF(I9 = "Surgery", "Needs TGH instructions", "No instructions needed") -> No instructions needed | S9: Standard Deviation | T9: 377.88414
A10: 9 | B10: 192 | C10: 107 | D10: Loki | E10: Dog | F10: Ragdoll | G10: 11/20/2023 | H10: DEN02 | I10: =_xlfn.XLOOKUP(H10,Charge_Reference!A:A,Charge_Reference!B:B) -> Dental Cleaning | J10: 249.9214 | K10: Rockville | L10: =IF(I10 = "Surgery", "Needs TGH instructions", "No instructions needed") -> No instructions needed | S10: Sample Variance | T10: 142796.42
A11: 10 | B11: 92 | C11: 20 | D11: Winston | E11: Dog | F11: Border Collie | G11: 05/28/2023 | H11: NT05 | I11: =_xlfn.XLOOKUP(H11,Charge_Reference!A:A,Charge_Reference!B:B) -> Nail Trim | J11: 866.7261 | K11: Frederick | L11: =IF(I11 = "Surgery", "Needs TGH instructions", "No instructions needed") -> No instructions needed | S11: Kurtosis | T11: -1.1986134
A12: 11 | B12: 124 | C12: 72 | D12: Max | E12: Dog | F12: Scottish Fold | G12: 06/01/2023 | H12: CHK03 | I12: =_xlfn.XLOOKUP(H12,Charge_Reference!A:A,Charge_Reference!B:B) -> Office Visit | J12: 738.0413 | K12: Frederick | L12: =IF(I12 = "Surgery", "Needs TGH instructions", "No instructions needed") -> No instructions needed | S12: Skewness | T12: 0.08376823
A13: 12 | B13: 17 | C13: 117 | D13: Oliver | E13: Dog | F13: Shih Tzu | G13: 08/08/2023 | H13: CHK03 | I13: =_xlfn.XLOOKUP(H13,Charge_Reference!A:A,Charge_Reference!B:B) -> Office Visit | J13: 66.0608 | K13: Baltimore | L13: =IF(I13 = "Surgery", "Needs TGH instructions", "No instructions needed") -> No instructions needed | S13: Range | T13: 1294.2561
A14: 13 | B14: 73 | C14: 23 | D14: Bentley | E14: Dog | F14: British Shorthair | G14: 03/19/2023 | H14: RAD08 | I14: =_xlfn.XLOOKUP(H14,Charge_Reference!A:A,Charge_Reference!B:B) -> Radiographs | J14: 228.2995 | K14: Baltimore | L14: =IF(I14 = "Surgery", "Needs TGH instructions", "No instructions needed") -> No instructions needed | S14: Minimum | T14: -294.6327
A15: 14 | B15: 14 | C15: 2 | D15: Rocky | E15: Dog | F15: Cocker Spaniel | G15: 04/02/2023 | H15: VAC01 | I15: =_xlfn.XLOOKUP(H15,Charge_Reference!A:A,Charge_Reference!B:B) -> Vaccination | J15: 500.188 | K15: Frederick | L15: =IF(I15 = "Surgery", "Needs TGH instructions", "No instructions needed") -> No instructions needed | S15: Maximum | T15: 999.6234
A16: 15 | B16: 171 | C16: 20 | D16: Coco | E16: Dog | F16: Great Dane | G16: 03/02/2023 | H16: SUR04 | I16: =_xlfn.XLOOKUP(H16,Charge_Reference!A:A,Charge_Reference!B:B) -> Surgery | J16: -290.9812 | K16: Baltimore | L16: =IF(I16 = "Surgery", "Needs TGH instructions", "No instructions needed") -> Needs TGH instructions | S16: Sum | T16: 169658.22
A17: 16 | B17: 59 | C17: 80 | D17: Charlie | E17: Dog | F17: Poodle | G17: 10/29/2023 | H17: RAD08 | I17: =_xlfn.XLOOKUP(H17,Charge_Reference!A:A,Charge_Reference!B:B) -> Radiographs | J17: 588.9633 | K17: Rockville | L17: =IF(I17 = "Surgery", "Needs TGH instructions", "No instructions needed") -> No instructions needed | S17: Count | T17: 500
A18: 17 | B18: 181 | C18: 139 | D18: Max | E18: Cat | F18: Shih Tzu | G18: 03/11/2023 | H18: EM06 | I18: =_xlfn.XLOOKUP(H18,Charge_Reference!A:A,Charge_Reference!B:B) -> Emergency Visit | J18: 364.0403 | K18: Frederick | L18: =IF(I18 = "Surgery", "Needs TGH instructions", "No instructions needed") -> No instructions needed
A19: 18 | B19: 157 | C19: 70 | D19: Oreo | E19: Cat | F19: Rottweiler | G19: 05/31/2023 | H19: BW07 | I19: =_xlfn.XLOOKUP(H19,Charge_Reference!A:A,Charge_Reference!B:B) -> Annual Bloodwork | J19: 387.5056 | K19: Rockville | L19: =IF(I19 = "Surgery", "Needs TGH instructions", "No instructions needed") -> No instructions needed
A20: 19 | B20: 8 | C20: 95 | D20: Blue | E20: Cat | F20: Doberman Pinscher | G20: 05/27/2023 | H20: EM06 | I20: =_xlfn.XLOOKUP(H20,Charge_Reference!A:A,Charge_Reference!B:B) -> Emergency Visit | J20: 879.7266 | K20: Frederick | L20: =IF(I20 = "Surgery", "Needs TGH instructions", "No instructions needed") -> No instructions needed
A21: 20 | B21: 173 | C21: 25 | D21: Rocky | E21: Cat | F21: Siamese | G21: 02/27/2023 | H21: NT05 | I21: =_xlfn.XLOOKUP(H21,Charge_Reference!A:A,Charge_Reference!B:B) -> Nail Trim | J21: 246.5149 | K21: Frederick | L21: =IF(I21 = "Surgery", "Needs TGH instructions", "No instructions needed") -> No instructions needed
A22: 21 | B22: 200 | C22: 127 | D22: Finn | E22: Dog | F22: Yorkshire Terrier | G22: 07/05/2023 | H22: SUR04 | I22: =_xlfn.XLOOKUP(H22,Charge_Reference!A:A,Charge_Reference!B:B) -> Surgery | J22: 999.6234 | K22: Baltimore | L22: =IF(I22 = "Surgery", "Needs TGH instructions", "No instructions needed") -> Needs TGH instructions
A23: 22 | B23: 3 | C23: 33 | D23: Moose | E23: Cat | F23: Poodle | G23: 10/15/2023 | H23: DEN02 | I23: =_xlfn.XLOOKUP(H23,Charge_Reference!A:A,Charge_Reference!B:B) -> Dental Cleaning | J23: -206.3467 | K23: Rockville | L23: =IF(I23 = "Surgery", "Needs TGH instructions", "No instructions needed") -> No instructions needed
A24: 23 | B24: 59 | C24: 119 | D24: Atlas | E24: Dog | F24: Boxer | G24: 12/03/2023 | H24: VAC01 | I24: =_xlfn.XLOOKUP(H24,Charge_Reference!A:A,Charge_Reference!B:B) -> Vaccination | J24: 248.8354 | K24: Rockville | L24: =IF(I24 = "Surgery", "Needs TGH instructions", "No instructions needed") -> No instructions needed
A25: 24 | B25: 92 | C25: 138 | D25: Duke | E25: Cat | F25: Abyssinian | G25: 10/23/2023 | H25: RAD08 | I25: =_xlfn.XLOOKUP(H25,Charge_Reference!A:A,Charge_Reference!B:B) -> Radiographs | J25: -288.6911 | K25: Rockville | L25: =IF(I25 = "Surgery", "Needs TGH instructions", "No instructions needed") -> No instructions needed
A26: 25 | B26: 35 | C26: 114 | D26: Remy | E26: Cat | F26: Abyssinian | G26: 07/17/2023 | H26: SUR04 | I26: =_xlfn.XLOOKUP(H26,Charge_Reference!A:A,Charge_Reference!B:B) -> Surgery | J26: -63.6229 | K26: Frederick | L26: =IF(I26 = "Surgery", "Needs TGH instructions", "No instructions needed") -> Needs TGH instructions
A27: 26 | B27: 21 | C27: 122 | D27: Lucy | E27: Cat | F27: Boston Terrier | G27: 02/11/2023 | H27: EM06 | I27: =_xlfn.XLOOKUP(H27,Charge_Reference!A:A,Charge_Reference!B:B) -> Emergency Visit | J27: 733.4284 | K27: Frederick | L27: =IF(I27 = "Surgery", "Needs TGH instructions", "No instructions needed") -> No instructions needed
A28: 27 | B28: 84 | C28: 34 | D28: Finn | E28: Dog | F28: Persian | G28: 09/25/2023 | H28: NT05 | I28: =_xlfn.XLOOKUP(H28,Charge_Reference!A:A,Charge_Reference!B:B) -> Nail Trim | J28: 652.8297 | K28: Baltimore | L28: =IF(I28 = "Surgery", "Needs TGH instructions", "No instructions needed") -> No instructions needed
A29: 28 | B29: 47 | C29: 57 | D29: Bentley | E29: Dog | F29: Border Collie | G29: 04/11/2023 | H29: BW07 | I29: =_xlfn.XLOOKUP(H29,Charge_Reference!A:A,Charge_Reference!B:B) -> Annual Bloodwork | J29: 514.8634 | K29: Rockville | L29: =IF(I29 = "Surgery", "Needs TGH instructions", "No instructions needed") -> No instructions needed
... A501: 500 | B501: 168 | C501: 72 | D501: Bentley | E501: Cat | F501: Border Collie | G501: 05/24/2023 | H501: NT05 | I501: =_xlfn.XLOOKUP(H501,Charge_Reference!A:A,Charge_Reference!B:B) -> Nail Trim | J501: 513.7263 | K501: Frederick | L501: =IF(I501 = "Surgery", "Needs TGH instructions", "No instructions needed") -> No instructions needed

Sheet Visits
A1: Visit_ID | B1: Pet_ID | C1: Owner_ID | D1: Pet_Name | E1: Species | F1: Breed | G1: Visit_Date | H1: Treatment | I1: Charge_Code | J1: Charge_Amount | K1: Clinic_Location
A2: 1 | B2: 47 | C2: 116 | D2: Winston | E2: DOG | F2: Shih Tzu | G2: 03/28/2023 | H2: Vaccnation | I2: SUR04 | J2: 939.0052 | K2: Rockville
A3: 2 | B3: 25 | C3: 37 | D3: Ellie | E3: DOG | F3: German Shepherd | G3: 01/09/2023 | H3: Vaccnation | I3: EM06 | J3: 725.9805 | K3: Rockville
A4: 3 | B4: 22 | C4: 35 | D4: Rocky | E4: Dog | F4: Beagle | G4: 11/14/2023 | H4: Vaccnation | I4: BW07 | J4: 349.3595 | K4: frederick
A5: 4 | B5: 63 | C5: 66 | D5: Ellie | E5: cat | F5: Yorkshire Terrier | G5: 01/02/2023 | H5: Checkup | I5: EM06 | J5: 78.2418 | K5: Frederick
A6: 5 | B6: 18 | C6: 101 | D6: Riley | E6: DOG | F6: Border Collie | G6: 11/05/2023 | H6: Vaccnation | I6: den02 | J6: 480.2783 | K6: Frederick
A7: 6 | B7: 71 | C7: 131 | D7: Shadow | E7: cat | F7: Chihuahua | G7: 10/19/2023 | H7: Surgery | I7: RAD08 | J7: 937.5625 | K7: Rockville
A8: 7 | B8: 92 | C8: 75 | D8: Rosie | E8: DOG | F8: Poodle | G8: 01/29/2023 | I8: VAC01 | J8: 650.0059 | K8: frederick
A9: 8 | B9: 12 | C9: 2 | D9: Nova | E9: DOG | F9: Labrador Retriever | G9: 04/07/2023 | H9: check up | I9: chk03 | J9: -244.7196 | K9: Frederick
A10: 9 | B10: 192 | C10: 107 | D10: Loki | E10: Dog | F10: Ragdoll | G10: 11/20/2023 | H10: Dental Cleaning | I10: DEN02 | J10: 249.9214 | K10: Rockville
A11: 10 | B11: 92 | C11: 20 | D11: Winston | E11: DOG | F11: Border Collie | G11: 05/28/2023 | H11: Vaccination | I11: nt05 | J11: 866.7261 | K11: frederick
A12: 11 | B12: 124 | C12: 72 | D12: Max | E12: Dog | F12: Scottish Fold | G12: 06/01/2023 | I12: chk03 | J12: 738.0413 | K12: Frederick
A13: 12 | B13: 17 | C13: 117 | D13: Oliver | E13: Dog | F13: Shih Tzu | G13: 08/08/2023 | H13: Vaccination | I13: CHK03 | J13: 66.0608 | K13: Baltimore
A14: 13 | B14: 73 | C14: 23 | D14: Bentley | E14: DOG | F14: British Shorthair | G14: 03/19/2023 | H14: Surgery | I14: RAD08 | J14: 228.2995 | K14: Baltimore
A15: 14 | B15: 14 | C15: 2 | D15: Rocky | E15: DOG | F15: Cocker Spaniel | G15: 04/02/2023 | H15: Vaccnation | I15: VAC01 | J15: 500.188 | K15: Frederick
A16: 15 | B16: 171 | C16: 20 | D16: Coco | E16: DOG | F16: Great Dane | G16: 03/02/2023 | H16: check up | I16: sur04 | J16: -290.9812 | K16: Baltimore
A17: 16 | B17: 59 | C17: 80 | D17: Charlie | E17: DOG | F17: Poodle | G17: 10/29/2023 | H17: Vaccination | I17: RAD08 | J17: 588.9633 | K17: Rockville
A18: 17 | B18: 181 | C18: 139 | D18: Max | E18: cat | F18: Shih Tzu | G18: 03/11/2023 | H18: Vaccnation | I18: EM06 | J18: 364.0403 | K18: frederick
A19: 18 | B19: 157 | C19: 70 | D19: Oreo | E19: Cat | F19: Rottweiler | G19: 05/31/2023 | H19: Vaccnation | I19: BW07 | J19: 387.5056 | K19: Rockville
A20: 19 | B20: 8 | C20: 95 | D20: Blue | E20: Cat | F20: Doberman Pinscher | G20: 05/27/2023 | I20: EM06 | J20: 879.7266 | K20: frederick
A21: 20 | B21: 173 | C21: 25 | D21: Rocky | E21: Cat | F21: Siamese | G21: 02/27/2023 | H21: Checkup | I21: NT05 | J21: 246.5149 | K21: frederick
A22: 21 | B22: 200 | C22: 127 | D22: Finn | E22: DOG | F22: Yorkshire Terrier | G22: 07/05/2023 | H22: Checkup | I22: SUR04 | J22: 999.6234 | K22: Baltimore
A23: 22 | B23: 3 | C23: 33 | D23: Moose | E23: cat | F23: Poodle | G23: 10/15/2023 | H23: Checkup | I23: den02 | J23: -206.3467 | K23: Rockville
A24: 23 | B24: 59 | C24: 119 | D24: Atlas | E24: Dog | F24: Boxer | G24: 12/03/2023 | I24: vac01 | J24: 248.8354 | K24: Rockville
A25: 24 | B25: 92 | C25: 138 | D25: Duke | E25: cat | F25: Abyssinian | G25: 10/23/2023 | H25: Checkup | I25: rad08 | J25: -288.6911 | K25: Rockville
A26: 25 | B26: 35 | C26: 114 | D26: Remy | E26: cat | F26: Abyssinian | G26: 07/17/2023 | H26: Surgery | I26: SUR04 | J26: -63.6229 | K26: Frederick
A27: 26 | B27: 21 | C27: 122 | D27: Lucy | E27: cat | F27: Boston Terrier | G27: 02/11/2023 | H27: Surgery | I27: EM06 | J27: 733.4284 | K27: Frederick
A28: 27 | B28: 84 | C28: 34 | D28: Finn | E28: DOG | F28: Persian | G28: 09/25/2023 | H28: check up | I28: NT05 | J28: 652.8297 | K28: Baltimore
A29: 28 | B29: 47 | C29: 57 | D29: Bentley | E29: DOG | F29: Border Collie | G29: 04/11/2023 | H29: Checkup | I29: BW07 | J29: 514.8634 | K29: Rockville
A30: 29 | B30: 18 | C30: 104 | D30: Winston | E30: DOG | F30: Sphynx | G30: 11/13/2023 | H30: Surgery | I30: CHK03 | J30: 6.1393 | K30: Rockville
A31: 30 | B31: 54 | C31: 79 | D31: Tucker | E31: Dog | F31: Chihuahua | G31: 05/26/2023 | H31: Dental Cleaning | I31: CHK03 | J31: 112.3904 | K31: Baltimore
A32: 31 | B32: 46 | C32: 147 | D32: Moose | E32: Dog | F32: Bulldog | G32: 01/01/2023 | H32: Vaccination | I32: VAC01 | J32: 777.2839 | K32: Frederick
A33: 32 | B33: 137 | C33: 134 | D33: Scout | E33: DOG | F33: Beagle | G33: 04/26/2023 | H33: Vaccination | I33: vac01 | J33: -96.3762 | K33: Frederick
A34: 33 | B34: 146 | C34: 18 | D34: Thor | E34: Dog | F34: Maine Coon | G34: 11/15/2023 | H34: Vaccnation | I34: EM06 | J34: -80.7615 | K34: frederick
A35: 34 | B35: 38 | C35: 115 | D35: Max | E35: Dog | F35: Bengal | G35: 07/29/2023 | H35: Checkup | I35: em06 | J35: -113.2574 | K35: Frederick
A36: 35 | B36: 111 | C36: 119 | D36: Cooper | E36: cat | F36: Great Dane | G36: 03/25/2023 | H36: Dental Cleaning | I36: sur04 | J36: 467.9106 | K36: frederick
... A38: 37 | B38: 159 | C38: 147 | D38: Oreo | E38: cat | F38: Shih Tzu | G38: 11/06/2023 | H38: Vaccnation | I38: EM06 | J38: -250.7664 | K38: frederick
A39: 38 | B39: 193 | C39: 58 | D39: Oreo | E39: DOG | F39: Cocker Spaniel | G39: 09/18/2023 | I39: EM06 | J39: -29.6434 | K39: Baltimore
A40: 39 | B40: 142 | C40: 82 | D40: Rocky | E40: Dog | F40: Rottweiler | G40: 03/21/2023 | H40: Vaccnation | I40: NT05 | J40: 249.845 | K40: Rockville
A41: 40 | B41: 50 | C41: 108 | D41: Stella | E41: DOG | F41: Boxer | G41: 09/06/2023 | H41: Checkup | I41: RAD08 | J41: 923.014 | K41: frederick
...

Sheet Owners
A1: Owner_ID | B1: Owner_Name | C1: Owner_Email | D1: Owner_Phone | E1: City | F1: State
A2: 1 | B2: Levi Baker | C2: levi.baker@test.com | D2: +1 (495) 310-2462 | E2: Baltimore | F2: MD
A3: 2 | B3: Dylan Morris | C3: dylan.morris@test.com | D3: +1 (845) 620-4973 | E3: Rockville | F3: MD
A4: 3 | B4: Evelyn Nelson | C4: evelyn.nelson@test.com | D4: +1 (413) 997-3147 | E4: Frederick | F4: MD
A5: 4 | B5: Sebastian Turner | C5: sebastian.turner@test.com | D5: +1 (724) 896-1144 | E5: Baltimore | F5: MD
A6: 5 | B6: Mateo Gonzalez | C6: mateo.gonzalez@test.com | D6: +1 (719) 406-4967 | E6: Rockville | F6: MD
A7: 6 | B7: Samuel Rogers | C7: samuel.rogers@test.com | D7: +1 (600) 906-4389 | E7: Baltimore | F7: MD
A8: 7 | B8: Mateo Thompson | C8: mateo.thompson@test.com | D8: +1 (760) 804-4262 | E8: Frederick | F8: MD
A9: 8 | B9: Luke Nelson | C9: luke.nelson@test.com | D9: +1 (873) 500-8562 | E9: Frederick | F9: MD
A10: 9 | B10: Henry Collins | C10: henry.collins@test.com | D10: +1 (253) 688-3755 | E10: Rockville | F10: MD
A11: 10 | B11: Mateo Edwards | C11: mateo.edwards@test.com | D11: +1 (559) 378-9024 | E11: Frederick | F11: MD
A12: 11 | B12: Anthony Carter | C12: anthony.carter@test.com | D12: +1 (850) 444-1358 | E12: Rockville | F12: MD
A13: 12 | B13: Leo Perez | C13: leo.perez@test.com | D13: +1 (706) 837-8678 | E13: Rockville | F13: MD
... A151: 150 | B151: Isaac Clark | C151: isaac.clark@test.com | D151: +1 (479) 581-5070 | E151: Frederick | F151: MD

Sheet Charge_Reference
A1: Charge_Code | B1: Expected_Treatment | C1: Standard_Amount
A2: VAC01 | B2: Vaccination | C2: 50
A3: DEN02 | B3: Dental Cleaning | C3: 400
A4: CHK03 | B4: Office Visit | C4: 150
A5: SUR04 | B5: Surgery | C5: 500
A6: NT05 | B6: Nail Trim | C6: 25
A7: EM06 | B7: Emergency Visit | C7: 300
A8: BW07 | B8: Annual Bloodwork | C8: 200
A9: RAD08 | B9: Radiographs | C9: 350
